Workbook

Sheet README
A1: MediBec - CyberRiskGuardian Risk Assessment Workbook
A3: Assessment period: next 12 months (October 2026 - September 2027). Currency: CAD. Cost basis: Year-1 = initial implementation + first-year recurring.
A4: Source: MediBec Business Case v2.0b (fictional teaching case, M.-A. Leger) and CyberRiskGuardian Excel Guide v1.0c formulas.
A5: All parameter values, CVSS vectors, costs and reductions are ANALYTICAL ESTIMATES — VALIDATION REQUIRED. Scores are relative decision-support indicators, not loss predictions.
A7: Colour legend: blue text = input you may edit | black = formula | green = link to another sheet | yellow fill = key assumption.
A9: Sheets:
A10: Parameters - risk appetite, multiplication factor, tolerance band (edit here).
A11: Inputs - S1-S10 quantitative parameters, CVSS v4.0 vector/score, reductions, confidence.
A12: Analyse - estimated, tolerated, mitigated, residual risk, ratio, classification, cost-effectiveness (live formulas).
A13: Portfolio - 13 initiatives, costs and scenario mapping; shared costs split equally across scenarios addressed (no double-counting).
A14: Sensitivity - lower / central / higher cases for five key scenarios (all parameters shifted by +/- delta).
A15: Case_View - case-native escalation view (s.8 of the case): T x E x I x (1 - C), with the 0.25 / 0.40 escalation thresholds.
... A25: How to use: change blue cells on Parameters / Inputs / Portfolio, then recalculate (Formulas > Calculate Now if manual).

Sheet Analyse
A1: Analyse - CyberRiskGuardian risk indices (Excel Guide v1.0c formulas; not KRIs)
A2: Green = linked from Inputs / Portfolio / Parameters; black = formula.
A4: ID | B4: Scenario | C4: Pb(A) | D4: Pb(psi,A) | E4: CVSS-B | F4: de | G4: dm | H4: mu(E) | I4: theta | J4: Appetite | K4: Factor | L4: Estimated risk | M4: Tolerated risk | N4: Pre-treatment ratio | O4: Allocated Y1 cost | P4: Prob. reduction | Q4: Impact reduction | R4: Mitigated | S4: Residual | T4: Residual / Tolerated | U4: Classification | V4: Cost-effectiveness (per $1k) | W4: Validity (P,Q in 0-1)
A5: =Inputs!A4 -> S1 | B5: =Inputs!B4 -> Credential compromise of clinical administrator accounts through phishing and MFA fatigue | C5: =Inputs!C4 -> 0.85 | D5: =Inputs!D4 -> 0.55 | E5: =Inputs!J4 -> 9.3 | F5: =Inputs!E4 -> 0.55 | G5: =Inputs!F4 -> 0.85 | H5: =Inputs!H4 -> 0.85 | I5: =Inputs!G4 -> 0.4 | J5: =Parameters!$B$4 -> 0.3 | K5: =Parameters!$B$5 -> 1000 | L5: =C5*D5*E5*((F5+G5)/2)*H5/I5*K5 -> 6467.2781 | M5: =C5*D5*E5*J5*H5/I5*K5 -> 2771.6906 | N5: =L5/M5 -> 2.3333333 | O5: =Portfolio!K17 -> 223888.89 | P5: =Inputs!K4 -> 0.8 | Q5: =Inputs!L4 -> 0.75 | R5: =L5*P5*Q5 -> 3880.3669 | S5: =L5-R5 -> 2586.9113 | T5: =S5/M5 -> 0.93333333 | U5: =IF(T5<Parameters!$B$6,"Below tolerance",IF(T5<=Parameters!$B$7,"Approximately at tolerance","Above tolerance")) -> Approximately at tolerance | V5: =IF(O5=0,0,(L5-S5)/O5*1000) -> 17.331663 | W5: =IF(AND(P5>=0,P5<=1,Q5>=0,Q5<=1),"OK","CHECK") -> OK
A6: =Inputs!A5 -> S2 | B6: =Inputs!B5 -> Ransomware disrupting EHR access and clinic operations across the network | C6: =Inputs!C5 -> 0.75 | D6: =Inputs!D5 -> 0.5 | E6: =Inputs!J5 -> 9.3 | F6: =Inputs!E5 -> 0.7 | G6: =Inputs!F5 -> 0.95 | H6: =Inputs!H5 -> 0.95 | I6: =Inputs!G5 -> 0.35 | J6: =Parameters!$B$4 -> 0.3 | K6: =Parameters!$B$5 -> 1000 | L6: =C6*D6*E6*((F6+G6)/2)*H6/I6*K6 -> 7809.5089 | M6: =C6*D6*E6*J6*H6/I6*K6 -> 2839.8214 | N6: =L6/M6 -> 2.75 | O6: =Portfolio!L17 -> 585888.89 | P6: =Inputs!K5 -> 0.75 | Q6: =Inputs!L5 -> 0.75 | R6: =L6*P6*Q6 -> 4392.8488 | S6: =L6-R6 -> 3416.6602 | T6: =S6/M6 -> 1.203125 | U6: =IF(T6<Parameters!$B$6,"Below tolerance",IF(T6<=Parameters!$B$7,"Approximately at tolerance","Above tolerance")) -> Above tolerance | V6: =IF(O6=0,0,(L6-S6)/O6*1000) -> 7.4977506 | W6: =IF(AND(P6>=0,P6<=1,Q6>=0,Q6<=1),"OK","CHECK") -> OK
A7: =Inputs!A6 -> S3 | B7: =Inputs!B6 -> Backup environment compromised, preventing recovery after a destructive attack | C7: =Inputs!C6 -> 0.55 | D7: =Inputs!D6 -> 0.5 | E7: =Inputs!J6 -> 9.2 | F7: =Inputs!E6 -> 0.6 | G7: =Inputs!F6 -> 0.9 | H7: =Inputs!H6 -> 0.9 | I7: =Inputs!G6 -> 0.35 | J7: =Parameters!$B$4 -> 0.3 | K7: =Parameters!$B$5 -> 1000 | L7: =C7*D7*E7*((F7+G7)/2)*H7/I7*K7 -> 4879.2857 | M7: =C7*D7*E7*J7*H7/I7*K7 -> 1951.7143 | N7: =L7/M7 -> 2.5 | O7: =Portfolio!M17 -> 423888.89 | P7: =Inputs!K6 -> 0.8 | Q7: =Inputs!L6 -> 0.85 | R7: =L7*P7*Q7 -> 3317.9143 | S7: =L7-R7 -> 1561.3714 | T7: =S7/M7 -> 0.8 | U7: =IF(T7<Parameters!$B$6,"Below tolerance",IF(T7<=Parameters!$B$7,"Approximately at tolerance","Above tolerance")) -> Below tolerance | V7: =IF(O7=0,0,(L7-S7)/O7*1000) -> 7.8273207 | W7: =IF(AND(P7>=0,P7<=1,Q7>=0,Q7<=1),"OK","CHECK") -> OK
A8: =Inputs!A7 -> S4 | B8: =Inputs!B7 -> Cloud medical-image transfer storage exposed, enabling bulk health-data exfiltration | C8: =Inputs!C7 -> 0.6 | D8: =Inputs!D7 -> 0.45 | E8: =Inputs!J7 -> 8.7 | F8: =Inputs!E7 -> 0.55 | G8: =Inputs!F7 -> 0.8 | H8: =Inputs!H7 -> 0.75 | I8: =Inputs!G7 -> 0.4 | J8: =Parameters!$B$4 -> 0.3 | K8: =Parameters!$B$5 -> 1000 | L8: =C8*D8*E8*((F8+G8)/2)*H8/I8*K8 -> 2972.9531 | M8: =C8*D8*E8*J8*H8/I8*K8 -> 1321.3125 | N8: =L8/M8 -> 2.25 | O8: =Portfolio!N17 -> 345555.56 | P8: =Inputs!K7 -> 0.85 | Q8: =Inputs!L7 -> 0.7 | R8: =L8*P8*Q8 -> 1768.9071 | S8: =L8-R8 -> 1204.046 | T8: =S8/M8 -> 0.91125 | U8: =IF(T8<Parameters!$B$6,"Below tolerance",IF(T8<=Parameters!$B$7,"Approximately at tolerance","Above tolerance")) -> Approximately at tolerance | V8: =IF(O8=0,0,(L8-S8)/O8*1000) -> 5.1190238 | W8: =IF(AND(P8>=0,P8<=1,Q8>=0,Q8<=1),"OK","CHECK") -> OK
A9: =Inputs!A8 -> S5 | B9: =Inputs!B8 -> Misuse of legitimate clinical, privileged or service-account access to extract patient records | C9: =Inputs!C8 -> 0.6 | D9: =Inputs!D8 -> 0.55 | E9: =Inputs!J8 -> 7.1 | F9: =Inputs!E8 -> 0.45 | G9: =Inputs!F8 -> 0.75 | H9: =Inputs!H8 -> 0.8 | I9: =Inputs!G8 -> 0.4 | J9: =Parameters!$B$4 -> 0.3 | K9: =Parameters!$B$5 -> 1000 | L9: =C9*D9*E9*((F9+G9)/2)*H9/I9*K9 -> 2811.6 | M9: =C9*D9*E9*J9*H9/I9*K9 -> 1405.8 | N9: =L9/M9 -> 2 | O9: =Portfolio!O17 -> 260555.56 | P9: =Inputs!K8 -> 0.6 | Q9: =Inputs!L8 -> 0.65 | R9: =L9*P9*Q9 -> 1096.524 | S9: =L9-R9 -> 1715.076 | T9: =S9/M9 -> 1.22 | U9: =IF(T9<Parameters!$B$6,"Below tolerance",IF(T9<=Parameters!$B$7,"Approximately at tolerance","Above tolerance")) -> Above tolerance | V9: =IF(O9=0,0,(L9-S9)/O9*1000) -> 4.2084077 | W9: =IF(AND(P9>=0,P9<=1,Q9>=0,Q9<=1),"OK","CHECK") -> OK
A10: =Inputs!A9 -> S6 | B10: =Inputs!B9 -> Exploitation of unpatched internet-facing or end-of-life systems | C10: =Inputs!C9 -> 0.8 | D10: =Inputs!D9 -> 0.5 | E10: =Inputs!J9 -> 10 | F10: =Inputs!E9 -> 0.6 | G10: =Inputs!F9 -> 0.9 | H10: =Inputs!H9 -> 0.85 | I10: =Inputs!G9 -> 0.4 | J10: =Parameters!$B$4 -> 0.3 | K10: =Parameters!$B$5 -> 1000 | L10: =C10*D10*E10*((F10+G10)/2)*H10/I10*K10 -> 6375 | M10: =C10*D10*E10*J10*H10/I10*K10 -> 2550 | N10: =L10/M10 -> 2.5 | O10: =Portfolio!P17 -> 320888.89 | P10: =Inputs!K9 -> 0.85 | Q10: =Inputs!L9 -> 0.7 | R10: =L10*P10*Q10 -> 3793.125 | S10: =L10-R10 -> 2581.875 | T10: =S10/M10 -> 1.0125 | U10: =IF(T10<Parameters!$B$6,"Below tolerance",IF(T10<=Parameters!$B$7,"Approximately at tolerance","Above tolerance")) -> Approximately at tolerance | V10: =IF(O10=0,0,(L10-S10)/O10*1000) -> 11.82068 | W10: =IF(AND(P10>=0,P10<=1,Q10>=0,Q10<=1),"OK","CHECK") -> OK
A11: =Inputs!A10 -> S7 | B11: =Inputs!B10 -> Connected medical device used as a foothold to disrupt clinical equipment and reach the EHR network | C11: =Inputs!C10 -> 0.45 | D11: =Inputs!D10 -> 0.5 | E11: =Inputs!J10 -> 8.7 | F11: =Inputs!E10 -> 0.55 | G11: =Inputs!F10 -> 0.95 | H11: =Inputs!H10 -> 0.9 | I11: =Inputs!G10 -> 0.35 | J11: =Parameters!$B$4 -> 0.3 | K11: =Parameters!$B$5 -> 1000 | L11: =C11*D11*E11*((F11+G11)/2)*H11/I11*K11 -> 3775.1786 | M11: =C11*D11*E11*J11*H11/I11*K11 -> 1510.0714 | N11: =L11/M11 -> 2.5 | O11: =Portfolio!Q17 -> 522000 | P11: =Inputs!K10 -> 0.7 | Q11: =Inputs!L10 -> 0.6 | R11: =L11*P11*Q11 -> 1585.575 | S11: =L11-R11 -> 2189.6036 | T11: =S11/M11 -> 1.45 | U11: =IF(T11<Parameters!$B$6,"Below tolerance",IF(T11<=Parameters!$B$7,"Approximately at tolerance","Above tolerance")) -> Above tolerance | V11: =IF(O11=0,0,(L11-S11)/O11*1000) -> 3.0375 | W11: =IF(AND(P11>=0,P11<=1,Q11>=0,Q11<=1),"OK","CHECK") -> OK
A12: =Inputs!A11 -> S8 | B12: =Inputs!B11 -> Detection and response gaps allow an intrusion to persist and escalate | C12: =Inputs!C11 -> 0.8 | D12: =Inputs!D11 -> 0.6 | E12: =Inputs!J11 -> 9.2 | F12: =Inputs!E11 -> 0.6 | G12: =Inputs!F11 -> 0.9 | H12: =Inputs!H11 -> 0.85 | I12: =Inputs!G11 -> 0.3 | J12: =Parameters!$B$4 -> 0.3 | K12: =Parameters!$B$5 -> 1000 | L12: =C12*D12*E12*((F12+G12)/2)*H12/I12*K12 -> 9384 | M12: =C12*D12*E12*J12*H12/I12*K12 -> 3753.6 | N12: =L12/M12 -> 2.5 | O12: =Portfolio!R17 -> 208888.89 | P12: =Inputs!K11 -> 0.7 | Q12: =Inputs!L11 -> 0.8 | R12: =L12*P12*Q12 -> 5255.04 | S12: =L12-R12 -> 4128.96 | T12: =S12/M12 -> 1.1 | U12: =IF(T12<Parameters!$B$6,"Below tolerance",IF(T12<=Parameters!$B$7,"Approximately at tolerance","Above tolerance")) -> Approximately at tolerance | V12: =IF(O12=0,0,(L12-S12)/O12*1000) -> 25.157106 | W12: =IF(AND(P12>=0,P12<=1,Q12>=0,Q12<=1),"OK","CHECK") -> OK
A13: =Inputs!A12 -> S9 | B13: =Inputs!B12 -> Compromise of a critical vendor with remote access to MediBec systems | C13: =Inputs!C12 -> 0.55 | D13: =Inputs!D12 -> 0.45 | E13: =Inputs!J12 -> 9 | F13: =Inputs!E12 -> 0.6 | G13: =Inputs!F12 -> 0.9 | H13: =Inputs!H12 -> 0.85 | I13: =Inputs!G12 -> 0.35 | J13: =Parameters!$B$4 -> 0.3 | K13: =Parameters!$B$5 -> 1000 | L13: =C13*D13*E13*((F13+G13)/2)*H13/I13*K13 -> 4057.2321 | M13: =C13*D13*E13*J13*H13/I13*K13 -> 1622.8929 | N13: =L13/M13 -> 2.5 | O13: =Portfolio!S17 -> 383888.89 | P13: =Inputs!K12 -> 0.55 | Q13: =Inputs!L12 -> 0.7 | R13: =L13*P13*Q13 -> 1562.0344 | S13: =L13-R13 -> 2495.1978 | T13: =S13/M13 -> 1.5375 | U13: =IF(T13<Parameters!$B$6,"Below tolerance",IF(T13<=Parameters!$B$7,"Approximately at tolerance","Above tolerance")) -> Above tolerance | V13: =IF(O13=0,0,(L13-S13)/O13*1000) -> 4.0689752 | W13: =IF(AND(P13>=0,P13<=1,Q13>=0,Q13<=1),"OK","CHECK") -> OK
A14: =Inputs!A13 -> S10 | B14: =Inputs!B13 -> Manipulation of patient, medication or billing records undermining clinical decisions | C14: =Inputs!C13 -> 0.3 | D14: =Inputs!D13 -> 0.4 | E14: =Inputs!J13 -> 8.3 | F14: =Inputs!E13 -> 0.55 | G14: =Inputs!F13 -> 0.95 | H14: =Inputs!H13 -> 0.95 | I14: =Inputs!G13 -> 0.4 | J14: =Parameters!$B$4 -> 0.3 | K14: =Parameters!$B$5 -> 1000 | L14: =C14*D14*E14*((F14+G14)/2)*H14/I14*K14 -> 1774.125 | M14: =C14*D14*E14*J14*H14/I14*K14 -> 709.65 | N14: =L14/M14 -> 2.5 | O14: =Portfolio!T17 -> 590555.56 | P14: =Inputs!K13 -> 0.7 | Q14: =Inputs!L13 -> 0.75 | R14: =L14*P14*Q14 -> 931.41562 | S14: =L14-R14 -> 842.70938 | T14: =S14/M14 -> 1.1875 | U14: =IF(T14<Parameters!$B$6,"Below tolerance",IF(T14<=Parameters!$B$7,"Approximately at tolerance","Above tolerance")) -> Above tolerance | V14: =IF(O14=0,0,(L14-S14)/O14*1000) -> 1.5771854 | W14: =IF(AND(P14>=0,P14<=1,Q14>=0,Q14<=1),"OK","CHECK") -> OK
B15: Portfolio totals | L15: =SUM(L5:L14) -> 50306.162 | M15: =SUM(M5:M14) -> 20436.553 | O15: =SUM(O5:O14) -> 3866000 | R15: =SUM(R5:R14) -> 27583.751 | S15: =SUM(S5:S14) -> 22722.411 | T15: =S15/M15 -> 1.1118514 | V15: =(L15-S15)/O15*1000 -> 7.1349589
B17: Interpretation: Residual/Tolerated simplifies to ((de+dm)/2) x (1 - P x Q) / Appetite - CVSS, probabilities, resilience and criticality scale magnitude (ranking) but cancel out of the tolerance test.

Sheet Parameters
A1: Global parameters
A3: Parameter | B3: Value | C3: Source / note
A4: Risk appetite (analyst estimate) | B4: 0.3 | C4: Analytical estimate — validation required. Case states 0.40 normalized tolerance; see report s.4.
A5: Multiplication factor | B5: 1000 | C5: Constant across all scenarios (Excel Guide worked example).
A6: Tolerance band - lower bound of 'approximately at' | B6: 0.9 | C6: Ratio < this = below tolerance
A7: Tolerance band - upper bound of 'approximately at' | B7: 1.1 | C7: Ratio > this = above tolerance
A8: Case appetite (for comparison) | B8: 0.4 | C8: Business case s.8
A9: Sensitivity delta | B9: 0.1 | C9: Shift applied in Sensitivity sheet
A10: Case escalation - executive review threshold | B10: 0.25 | C10: Business case s.8
A11: Case escalation - Board acceptance threshold | B11: 0.4 | C11: Business case s.8

Sheet Inputs
A1: Scenario inputs (0-1 scale unless stated) - Analytical estimates — validation required
A3: ID | B3: Scenario | C3: Pb(A) | D3: Pb(psi,A) | E3: de | F3: dm | G3: theta | H3: mu(E) | I3: CVSS v4.0 vector | J3: CVSS-B | K3: Prob. reduction | L3: Impact reduction | M3: Conf Pb(A) | N3: Conf Pb(psi,A) | O3: Conf de | P3: Conf dm | Q3: Conf theta | R3: Conf mu
A4: S1 | B4: Credential compromise of clinical administrator accounts through phishing and MFA fatigue | C4: 0.85 | D4: 0.55 | E4: 0.55 | F4: 0.85 | G4: 0.4 | H4: 0.85 | I4: CVSS:4.0/AV:N/AC:L/AT:N/PR:N/UI:A/VC:H/VI:H/VA:N/SC:H/SI:L/SA:L | J4: 9.3 | K4: 0.8 | L4: 0.75 | M4: Medium | N4: Low | O4: Medium | P4: Medium | Q4: Medium | R4: High
A5: S2 | B5: Ransomware disrupting EHR access and clinic operations across the network | C5: 0.75 | D5: 0.5 | E5: 0.7 | F5: 0.95 | G5: 0.35 | H5: 0.95 | I5: CVSS:4.0/AV:L/AC:L/AT:N/PR:N/UI:P/VC:H/VI:H/VA:H/SC:H/SI:H/SA:H | J5: 9.3 | K5: 0.75 | L5: 0.75 | M5: Medium | N5: Low | O5: Medium | P5: Medium | Q5: Medium | R5: High
A6: S3 | B6: Backup environment compromised, preventing recovery after a destructive attack | C6: 0.55 | D6: 0.5 | E6: 0.6 | F6: 0.9 | G6: 0.35 | H6: 0.9 | I6: CVSS:4.0/AV:N/AC:L/AT:N/PR:H/UI:N/VC:H/VI:H/VA:H/SC:N/SI:N/SA:H | J6: 9.2 | K6: 0.8 | L6: 0.85 | M6: Medium | N6: Low | O6: Medium | P6: Medium | Q6: Medium | R6: High
A7: S4 | B7: Cloud medical-image transfer storage exposed, enabling bulk health-data exfiltration | C7: 0.6 | D7: 0.45 | E7: 0.55 | F7: 0.8 | G7: 0.4 | H7: 0.75 | I7: CVSS:4.0/AV:N/AC:L/AT:N/PR:N/UI:N/VC:H/VI:N/VA:N/SC:N/SI:N/SA:N | J7: 8.7 | K7: 0.85 | L7: 0.7 | M7: Medium | N7: Low | O7: Medium | P7: Medium | Q7: Low | R7: Medium
A8: S5 | B8: Misuse of legitimate clinical, privileged or service-account access to extract patient records | C8: 0.6 | D8: 0.55 | E8: 0.45 | F8: 0.75 | G8: 0.4 | H8: 0.8 | I8: CVSS:4.0/AV:N/AC:L/AT:N/PR:L/UI:N/VC:H/VI:L/VA:N/SC:N/SI:N/SA:N | J8: 7.1 | K8: 0.6 | L8: 0.65 | M8: Medium | N8: Medium | O8: Medium | P8: Medium | Q8: Medium | R8: High
A9: S6 | B9: Exploitation of unpatched internet-facing or end-of-life systems | C9: 0.8 | D9: 0.5 | E9: 0.6 | F9: 0.9 | G9: 0.4 | H9: 0.85 | I9: CVSS:4.0/AV:N/AC:L/AT:N/PR:N/UI:N/VC:H/VI:H/VA:H/SC:H/SI:H/SA:H | J9: 10 | K9: 0.85 | L9: 0.7 | M9: Medium | N9: Low | O9: Medium | P9: Medium | Q9: Medium | R9: High
A10: S7 | B10: Connected medical device used as a foothold to disrupt clinical equipment and reach the EHR network | C10: 0.45 | D10: 0.5 | E10: 0.55 | F10: 0.95 | G10: 0.35 | H10: 0.9 | I10: CVSS:4.0/AV:A/AC:L/AT:N/PR:N/UI:N/VC:H/VI:H/VA:H/SC:L/SI:L/SA:L | J10: 8.7 | K10: 0.7 | L10: 0.6 | M10: Low | N10: Low | O10: Medium | P10: Medium | Q10: Medium | R10: High
A11: S8 | B11: Detection and response gaps allow an intrusion to persist and escalate | C11: 0.8 | D11: 0.6 | E11: 0.6 | F11: 0.9 | G11: 0.3 | H11: 0.85 | I11: CVSS:4.0/AV:L/AC:L/AT:N/PR:N/UI:P/VC:H/VI:H/VA:L/SC:H/SI:L/SA:L | J11: 9.2 | K11: 0.7 | L11: 0.8 | M11: Medium | N11: Medium | O11: Medium | P11: Medium | Q11: Medium | R11: High
A12: S9 | B12: Compromise of a critical vendor with remote access to MediBec systems | C12: 0.55 | D12: 0.45 | E12: 0.6 | F12: 0.9 | G12: 0.35 | H12: 0.85 | I12: CVSS:4.0/AV:N/AC:L/AT:P/PR:L/UI:N/VC:H/VI:H/VA:H/SC:H/SI:H/SA:H | J12: 9 | K12: 0.55 | L12: 0.7 | M12: Low | N12: Low | O12: Medium | P12: Medium | Q12: Low | R12: High
A13: S10 | B13: Manipulation of patient, medication or billing records undermining clinical decisions | C13: 0.3 | D13: 0.4 | E13: 0.55 | F13: 0.95 | G13: 0.4 | H13: 0.95 | I13: CVSS:4.0/AV:N/AC:L/AT:N/PR:L/UI:N/VC:L/VI:H/VA:N/SC:N/SI:H/SA:N | J13: 8.3 | K13: 0.7 | L13: 0.75 | M13: Low | N13: Low | O13: Medium | P13: Medium | Q13: Low | R13: High

Sheet Portfolio
A1: Recommended treatment portfolio (indicative CAD estimates - not quotations or approved budgets)
A3: ID | B3: Initiative | C3: Owner | D3: Priority | E3: Type | F3: Initial cost | G3: Recurring / yr | H3: Year-1 cost | I3: # scenarios | J3: Y1 per scenario | K3: S1 | L3: S2 | M3: S3 | N3: S4 | O3: S5 | P3: S6 | Q3: S7 | R3: S8 | S3: S9 | T3: S10 | U3: Start | V3: End | W3: Success indicator
A4: I01 | B4: Phishing-resistant MFA and conditional access | C4: CIO / Cybersecurity lead | D4: Immediate | E4: Prevention | F4: 180000 | G4: 60000 | H4: =F4+G4 -> 240000 | I4: =SUM(K4:T4) -> 4 | J4: =IF(I4=0,0,H4/I4) -> 60000 | K4: 1 | L4: 0 | M4: 0 | N4: 0 | O4: 0 | P4: 0 | Q4: 0 | R4: 1 | S4: 1 | T4: 1 | U4: Month 0 | V4: Month 6 | W4: 100% privileged and remote-access accounts on phishing-resistant MFA
A5: I02 | B5: Privileged access and service-account management (PAM) | C5: Cybersecurity lead | D5: Near-term | E5: Prevention / Governance | F5: 250000 | G5: 80000 | H5: =F5+G5 -> 330000 | I5: =SUM(K5:T5) -> 6 | J5: =IF(I5=0,0,H5/I5) -> 55000 | K5: 1 | L5: 1 | M5: 1 | N5: 0 | O5: 1 | P5: 0 | Q5: 0 | R5: 0 | S5: 1 | T5: 1 | U5: Month 2 | V5: Month 12 | W5: 0 standing domain-admin accounts; 100% service accounts vaulted
A6: I03 | B6: 24/7 managed detection and response with centralized logging | C6: Cybersecurity lead | D6: Immediate | E6: Detection / Response | F6: 200000 | G6: 420000 | H6: =F6+G6 -> 620000 | I6: =SUM(K6:T6) -> 9 | J6: =IF(I6=0,0,H6/I6) -> 68888.889 | K6: 1 | L6: 1 | M6: 1 | N6: 1 | O6: 1 | P6: 1 | Q6: 0 | R6: 1 | S6: 1 | T6: 1 | U6: Month 0 | V6: Month 6 | W6: MTTD < 1 h, MTTC < 4 h for high-severity alerts; >95% critical log sources
A7: I04 | B7: Immutable and isolated backup with tested recovery | C7: CIO (Infrastructure) | D7: Immediate | E7: Recovery / Resilience | F7: 300000 | G7: 90000 | H7: =F7+G7 -> 390000 | I7: =SUM(K7:T7) -> 3 | J7: =IF(I7=0,0,H7/I7) -> 130000 | K7: 0 | L7: 1 | M7: 1 | N7: 0 | O7: 0 | P7: 0 | Q7: 0 | R7: 0 | S7: 0 | T7: 1 | U7: Month 0 | V7: Month 9 | W7: 100% crown-jewel restore tests pass within RTO
A8: I05 | B8: Risk-based vulnerability and patch management | C8: CIO / Cybersecurity lead | D8: Near-term | E8: Prevention | F8: 150000 | G8: 216000 | H8: =F8+G8 -> 366000 | I8: =SUM(K8:T8) -> 3 | J8: =IF(I8=0,0,H8/I8) -> 122000 | K8: 0 | L8: 1 | M8: 0 | N8: 0 | O8: 0 | P8: 1 | Q8: 1 | R8: 0 | S8: 0 | T8: 0 | U8: Month 1 | V8: Month 9 | W8: >95% critical vulns remediated within SLA; 0 unsupported internet-facing systems
A9: I06 | B9: Network segmentation and network access control | C9: CIO (Infrastructure) | D9: Planned | E9: Prevention / Resilience | F9: 450000 | G9: 70000 | H9: =F9+G9 -> 520000 | I9: =SUM(K9:T9) -> 4 | J9: =IF(I9=0,0,H9/I9) -> 130000 | K9: 0 | L9: 1 | M9: 1 | N9: 0 | O9: 0 | P9: 1 | Q9: 1 | R9: 0 | S9: 0 | T9: 0 | U9: Month 6 | V9: Month 24 | W9: 100% medical devices and guest Wi-Fi in isolated segments
A10: I07 | B10: Medical device security programme | C10: Biomedical engineering / Clinical Ops | D10: Near-term | E10: Identify / Detection | F10: 180000 | G10: 90000 | H10: =F10+G10 -> 270000 | I10: =SUM(K10:T10) -> 1 | J10: =IF(I10=0,0,H10/I10) -> 270000 | K10: 0 | L10: 0 | M10: 0 | N10: 0 | O10: 0 | P10: 0 | Q10: 1 | R10: 0 | S10: 0 | T10: 0 | U10: Month 3 | V10: Month 12 | W10: 100% networked devices inventoried and risk-rated
A11: I08 | B11: Cloud security posture and secure image transfer | C11: CIO / Radiology lead | D11: Immediate | E11: Prevention / Detection | F11: 120000 | G11: 60000 | H11: =F11+G11 -> 180000 | I11: =SUM(K11:T11) -> 1 | J11: =IF(I11=0,0,H11/I11) -> 180000 | K11: 0 | L11: 0 | M11: 0 | N11: 1 | O11: 0 | P11: 0 | Q11: 0 | R11: 0 | S11: 0 | T11: 0 | U11: Month 0 | V11: Month 6 | W11: 0 publicly accessible storage objects; 100% object access logged
A12: I09 | B12: Data access governance and EHR privacy monitoring | C12: Privacy officer / CIO | D12: Near-term | E12: Governance / Detection | F12: 200000 | G12: 90000 | H12: =F12+G12 -> 290000 | I12: =SUM(K12:T12) -> 3 | J12: =IF(I12=0,0,H12/I12) -> 96666.667 | K12: 0 | L12: 0 | M12: 0 | N12: 1 | O12: 1 | P12: 0 | Q12: 0 | R12: 0 | S12: 0 | T12: 1 | U12: Month 3 | V12: Month 12 | W12: 100% EHR roles recertified quarterly; bulk-access alerts reviewed within 24 h
A13: I10 | B13: Third-party cyber risk management | C13: Procurement / Cybersecurity lead | D13: Near-term | E13: Governance | F13: 90000 | G13: 70000 | H13: =F13+G13 -> 160000 | I13: =SUM(K13:T13) -> 1 | J13: =IF(I13=0,0,H13/I13) -> 160000 | K13: 0 | L13: 0 | M13: 0 | N13: 0 | O13: 0 | P13: 0 | Q13: 0 | R13: 0 | S13: 1 | T13: 0 | U13: Month 2 | V13: Month 12 | W13: 100% critical vendors assessed and under revised clauses
A14: I11 | B14: Incident response and clinical continuity readiness | C14: Cybersecurity lead / Clinical Ops | D14: Immediate | E14: Response / Resilience | F14: 120000 | G14: 80000 | H14: =F14+G14 -> 200000 | I14: =SUM(K14:T14) -> 5 | J14: =IF(I14=0,0,H14/I14) -> 40000 | K14: 0 | L14: 1 | M14: 1 | N14: 0 | O14: 0 | P14: 0 | Q14: 0 | R14: 1 | S14: 1 | T14: 1 | U14: Month 0 | V14: Month 6 | W14: 2 tabletops/year; all 10 clinics with tested downtime procedures
A15: I12 | B15: Governance, awareness and risk reporting | C15: Cybersecurity lead / Executive sponsor | D15: Immediate | E15: Governance | F15: 70000 | G15: 90000 | H15: =F15+G15 -> 160000 | I15: =SUM(K15:T15) -> 4 | J15: =IF(I15=0,0,H15/I15) -> 40000 | K15: 1 | L15: 1 | M15: 0 | N15: 0 | O15: 1 | P15: 0 | Q15: 0 | R15: 1 | S15: 0 | T15: 0 | U15: Month 0 | V15: Month 3 | W15: Quarterly KRI report delivered; phishing report rate > 70%
A16: I13 | B16: Clinical data integrity controls | C16: CIO / Clinical Ops / Pharmacy lead | D16: Planned | E16: Detection / Recovery | F16: 100000 | G16: 40000 | H16: =F16+G16 -> 140000 | I16: =SUM(K16:T16) -> 1 | J16: =IF(I16=0,0,H16/I16) -> 140000 | K16: 0 | L16: 0 | M16: 0 | N16: 0 | O16: 0 | P16: 0 | Q16: 0 | R16: 0 | S16: 0 | T16: 1 | U16: Month 6 | V16: Month 15 | W16: 100% critical record changes attributable and reconciled
B17: TOTAL (each initiative counted once) | F17: =SUM(F4:F16) -> 2410000 | G17: =SUM(G4:G16) -> 1456000 | H17: =SUM(H4:H16) -> 3866000 | K17: =SUMPRODUCT(K4:K16,$J$4:$J$16) -> 223888.89 | L17: =SUMPRODUCT(L4:L16,$J$4:$J$16) -> 585888.89 | M17: =SUMPRODUCT(M4:M16,$J$4:$J$16) -> 423888.89 | N17: =SUMPRODUCT(N4:N16,$J$4:$J$16) -> 345555.56 | O17: =SUMPRODUCT(O4:O16,$J$4:$J$16) -> 260555.56 | P17: =SUMPRODUCT(P4:P16,$J$4:$J$16) -> 320888.89 | Q17: =SUMPRODUCT(Q4:Q16,$J$4:$J$16) -> 522000 | R17: =SUMPRODUCT(R4:R16,$J$4:$J$16) -> 208888.89 | ... T17: =SUMPRODUCT(T4:T16,$J$4:$J$16) -> 590555.56
B18: Check: sum of scenario allocations - portfolio Year-1 total (should be 0) | H18: =SUM(K17:T17)-H17 -> 0
B20: Allocation assumption: each initiative's Year-1 cost is split equally across the scenarios it addresses, so shared controls are never charged in full to several scenarios.
B21: Cyber-insurance premium is excluded (Information gap - broker quotation required).

Sheet Sensitivity
A1: Sensitivity - lower / central / higher cases
A2: Lower case: Pb(A), Pb(psi,A), de, dm -delta; theta +delta; reductions +delta. Higher case: the reverse. Values clamped to [0.05, 0.99].
A4: ID | B4: Case | C4: Shift | D4: Pb(A) | E4: Pb(psi,A) | F4: de | G4: dm | H4: theta | I4: mu | J4: CVSS | K4: P red | L4: I red | M4: Estimated | N4: Tolerated | O4: Residual | P4: Ratio | Q4: Classification
A5: S2 | B5: Lower | C5: =-1*Parameters!$B$9 -> -0.1 | D5: =MAX(0.05,MIN(0.99,Inputs!C5+C5)) -> 0.65 | E5: =MAX(0.05,MIN(0.99,Inputs!D5+C5)) -> 0.4 | F5: =MAX(0.05,MIN(0.99,Inputs!E5+C5)) -> 0.6 | G5: =MAX(0.05,MIN(0.99,Inputs!F5+C5)) -> 0.85 | H5: =MAX(0.05,MIN(0.99,Inputs!G5-C5)) -> 0.45 | I5: =Inputs!H5 -> 0.95 | J5: =Inputs!J5 -> 9.3 | K5: =MAX(0.05,MIN(0.99,Inputs!K5-C5)) -> 0.85 | L5: =MAX(0.05,MIN(0.99,Inputs!L5-C5)) -> 0.85 | M5: =D5*E5*J5*((F5+G5)/2)*I5/H5*Parameters!$B$5 -> 3700.8833 | N5: =D5*E5*J5*Parameters!$B$4*I5/H5*Parameters!$B$5 -> 1531.4 | O5: =M5-M5*K5*L5 -> 1026.9951 | P5: =O5/N5 -> 0.670625 | Q5: =IF(P5<Parameters!$B$6,"Below tolerance",IF(P5<=Parameters!$B$7,"Approximately at tolerance","Above tolerance")) -> Below tolerance
A6: S2 | B6: Central | C6: =0*Parameters!$B$9 -> 0 | D6: =MAX(0.05,MIN(0.99,Inputs!C5+C6)) -> 0.75 | E6: =MAX(0.05,MIN(0.99,Inputs!D5+C6)) -> 0.5 | F6: =MAX(0.05,MIN(0.99,Inputs!E5+C6)) -> 0.7 | G6: =MAX(0.05,MIN(0.99,Inputs!F5+C6)) -> 0.95 | H6: =MAX(0.05,MIN(0.99,Inputs!G5-C6)) -> 0.35 | I6: =Inputs!H5 -> 0.95 | J6: =Inputs!J5 -> 9.3 | K6: =MAX(0.05,MIN(0.99,Inputs!K5-C6)) -> 0.75 | L6: =MAX(0.05,MIN(0.99,Inputs!L5-C6)) -> 0.75 | M6: =D6*E6*J6*((F6+G6)/2)*I6/H6*Parameters!$B$5 -> 7809.5089 | N6: =D6*E6*J6*Parameters!$B$4*I6/H6*Parameters!$B$5 -> 2839.8214 | O6: =M6-M6*K6*L6 -> 3416.6602 | P6: =O6/N6 -> 1.203125 | Q6: =IF(P6<Parameters!$B$6,"Below tolerance",IF(P6<=Parameters!$B$7,"Approximately at tolerance","Above tolerance")) -> Above tolerance
A7: S2 | B7: Higher | C7: =1*Parameters!$B$9 -> 0.1 | D7: =MAX(0.05,MIN(0.99,Inputs!C5+C7)) -> 0.85 | E7: =MAX(0.05,MIN(0.99,Inputs!D5+C7)) -> 0.6 | F7: =MAX(0.05,MIN(0.99,Inputs!E5+C7)) -> 0.8 | G7: =MAX(0.05,MIN(0.99,Inputs!F5+C7)) -> 0.99 | H7: =MAX(0.05,MIN(0.99,Inputs!G5-C7)) -> 0.25 | I7: =Inputs!H5 -> 0.95 | J7: =Inputs!J5 -> 9.3 | K7: =MAX(0.05,MIN(0.99,Inputs!K5-C7)) -> 0.65 | L7: =MAX(0.05,MIN(0.99,Inputs!L5-C7)) -> 0.65 | M7: =D7*E7*J7*((F7+G7)/2)*I7/H7*Parameters!$B$5 -> 16130.943 | N7: =D7*E7*J7*Parameters!$B$4*I7/H7*Parameters!$B$5 -> 5407.02 | O7: =M7-M7*K7*L7 -> 9315.6196 | P7: =O7/N7 -> 1.722875 | Q7: =IF(P7<Parameters!$B$6,"Below tolerance",IF(P7<=Parameters!$B$7,"Approximately at tolerance","Above tolerance")) -> Above tolerance
A8: S7 | B8: Lower | C8: =-1*Parameters!$B$9 -> -0.1 | D8: =MAX(0.05,MIN(0.99,Inputs!C10+C8)) -> 0.35 | E8: =MAX(0.05,MIN(0.99,Inputs!D10+C8)) -> 0.4 | F8: =MAX(0.05,MIN(0.99,Inputs!E10+C8)) -> 0.45 | G8: =MAX(0.05,MIN(0.99,Inputs!F10+C8)) -> 0.85 | H8: =MAX(0.05,MIN(0.99,Inputs!G10-C8)) -> 0.45 | I8: =Inputs!H10 -> 0.9 | J8: =Inputs!J10 -> 8.7 | K8: =MAX(0.05,MIN(0.99,Inputs!K10-C8)) -> 0.8 | L8: =MAX(0.05,MIN(0.99,Inputs!L10-C8)) -> 0.7 | M8: =D8*E8*J8*((F8+G8)/2)*I8/H8*Parameters!$B$5 -> 1583.4 | N8: =D8*E8*J8*Parameters!$B$4*I8/H8*Parameters!$B$5 -> 730.8 | O8: =M8-M8*K8*L8 -> 696.696 | P8: =O8/N8 -> 0.95333333 | Q8: =IF(P8<Parameters!$B$6,"Below tolerance",IF(P8<=Parameters!$B$7,"Approximately at tolerance","Above tolerance")) -> Approximately at tolerance
A9: S7 | B9: Central | C9: =0*Parameters!$B$9 -> 0 | D9: =MAX(0.05,MIN(0.99,Inputs!C10+C9)) -> 0.45 | E9: =MAX(0.05,MIN(0.99,Inputs!D10+C9)) -> 0.5 | F9: =MAX(0.05,MIN(0.99,Inputs!E10+C9)) -> 0.55 | G9: =MAX(0.05,MIN(0.99,Inputs!F10+C9)) -> 0.95 | H9: =MAX(0.05,MIN(0.99,Inputs!G10-C9)) -> 0.35 | I9: =Inputs!H10 -> 0.9 | J9: =Inputs!J10 -> 8.7 | K9: =MAX(0.05,MIN(0.99,Inputs!K10-C9)) -> 0.7 | L9: =MAX(0.05,MIN(0.99,Inputs!L10-C9)) -> 0.6 | M9: =D9*E9*J9*((F9+G9)/2)*I9/H9*Parameters!$B$5 -> 3775.1786 | N9: =D9*E9*J9*Parameters!$B$4*I9/H9*Parameters!$B$5 -> 1510.0714 | O9: =M9-M9*K9*L9 -> 2189.6036 | P9: =O9/N9 -> 1.45 | Q9: =IF(P9<Parameters!$B$6,"Below tolerance",IF(P9<=Parameters!$B$7,"Approximately at tolerance","Above tolerance")) -> Above tolerance
A10: S7 | B10: Higher | C10: =1*Parameters!$B$9 -> 0.1 | D10: =MAX(0.05,MIN(0.99,Inputs!C10+C10)) -> 0.55 | E10: =MAX(0.05,MIN(0.99,Inputs!D10+C10)) -> 0.6 | F10: =MAX(0.05,MIN(0.99,Inputs!E10+C10)) -> 0.65 | G10: =MAX(0.05,MIN(0.99,Inputs!F10+C10)) -> 0.99 | H10: =MAX(0.05,MIN(0.99,Inputs!G10-C10)) -> 0.25 | I10: =Inputs!H10 -> 0.9 | J10: =Inputs!J10 -> 8.7 | K10: =MAX(0.05,MIN(0.99,Inputs!K10-C10)) -> 0.6 | L10: =MAX(0.05,MIN(0.99,Inputs!L10-C10)) -> 0.5 | M10: =D10*E10*J10*((F10+G10)/2)*I10/H10*Parameters!$B$5 -> 8475.192 | N10: =D10*E10*J10*Parameters!$B$4*I10/H10*Parameters!$B$5 -> 3100.68 | O10: =M10-M10*K10*L10 -> 5932.6344 | P10: =O10/N10 -> 1.9133333 | Q10: =IF(P10<Parameters!$B$6,"Below tolerance",IF(P10<=Parameters!$B$7,"Approximately at tolerance","Above tolerance")) -> Above tolerance
A11: S9 | B11: Lower | C11: =-1*Parameters!$B$9 -> -0.1 | D11: =MAX(0.05,MIN(0.99,Inputs!C12+C11)) -> 0.45 | E11: =MAX(0.05,MIN(0.99,Inputs!D12+C11)) -> 0.35 | F11: =MAX(0.05,MIN(0.99,Inputs!E12+C11)) -> 0.5 | G11: =MAX(0.05,MIN(0.99,Inputs!F12+C11)) -> 0.8 | H11: =MAX(0.05,MIN(0.99,Inputs!G12-C11)) -> 0.45 | I11: =Inputs!H12 -> 0.85 | J11: =Inputs!J12 -> 9 | K11: =MAX(0.05,MIN(0.99,Inputs!K12-C11)) -> 0.65 | L11: =MAX(0.05,MIN(0.99,Inputs!L12-C11)) -> 0.8 | M11: =D11*E11*J11*((F11+G11)/2)*I11/H11*Parameters!$B$5 -> 1740.375 | N11: =D11*E11*J11*Parameters!$B$4*I11/H11*Parameters!$B$5 -> 803.25 | O11: =M11-M11*K11*L11 -> 835.38 | P11: =O11/N11 -> 1.04 | Q11: =IF(P11<Parameters!$B$6,"Below tolerance",IF(P11<=Parameters!$B$7,"Approximately at tolerance","Above tolerance")) -> Approximately at tolerance
A12: S9 | B12: Central | C12: =0*Parameters!$B$9 -> 0 | D12: =MAX(0.05,MIN(0.99,Inputs!C12+C12)) -> 0.55 | E12: =MAX(0.05,MIN(0.99,Inputs!D12+C12)) -> 0.45 | F12: =MAX(0.05,MIN(0.99,Inputs!E12+C12)) -> 0.6 | G12: =MAX(0.05,MIN(0.99,Inputs!F12+C12)) -> 0.9 | H12: =MAX(0.05,MIN(0.99,Inputs!G12-C12)) -> 0.35 | I12: =Inputs!H12 -> 0.85 | J12: =Inputs!J12 -> 9 | K12: =MAX(0.05,MIN(0.99,Inputs!K12-C12)) -> 0.55 | L12: =MAX(0.05,MIN(0.99,Inputs!L12-C12)) -> 0.7 | M12: =D12*E12*J12*((F12+G12)/2)*I12/H12*Parameters!$B$5 -> 4057.2321 | N12: =D12*E12*J12*Parameters!$B$4*I12/H12*Parameters!$B$5 -> 1622.8929 | O12: =M12-M12*K12*L12 -> 2495.1978 | P12: =O12/N12 -> 1.5375 | Q12: =IF(P12<Parameters!$B$6,"Below tolerance",IF(P12<=Parameters!$B$7,"Approximately at tolerance","Above tolerance")) -> Above tolerance
A13: S9 | B13: Higher | C13: =1*Parameters!$B$9 -> 0.1 | D13: =MAX(0.05,MIN(0.99,Inputs!C12+C13)) -> 0.65 | E13: =MAX(0.05,MIN(0.99,Inputs!D12+C13)) -> 0.55 | F13: =MAX(0.05,MIN(0.99,Inputs!E12+C13)) -> 0.7 | G13: =MAX(0.05,MIN(0.99,Inputs!F12+C13)) -> 0.99 | H13: =MAX(0.05,MIN(0.99,Inputs!G12-C13)) -> 0.25 | I13: =Inputs!H12 -> 0.85 | J13: =Inputs!J12 -> 9 | K13: =MAX(0.05,MIN(0.99,Inputs!K12-C13)) -> 0.45 | L13: =MAX(0.05,MIN(0.99,Inputs!L12-C13)) -> 0.6 | M13: =D13*E13*J13*((F13+G13)/2)*I13/H13*Parameters!$B$5 -> 9243.8775 | N13: =D13*E13*J13*Parameters!$B$4*I13/H13*Parameters!$B$5 -> 3281.85 | O13: =M13-M13*K13*L13 -> 6748.0306 | P13: =O13/N13 -> 2.0561667 | Q13: =IF(P13<Parameters!$B$6,"Below tolerance",IF(P13<=Parameters!$B$7,"Approximately at tolerance","Above tolerance")) -> Above tolerance
A14: S1 | B14: Lower | C14: =-1*Parameters!$B$9 -> -0.1 | D14: =MAX(0.05,MIN(0.99,Inputs!C4+C14)) -> 0.75 | E14: =MAX(0.05,MIN(0.99,Inputs!D4+C14)) -> 0.45 | F14: =MAX(0.05,MIN(0.99,Inputs!E4+C14)) -> 0.45 | G14: =MAX(0.05,MIN(0.99,Inputs!F4+C14)) -> 0.75 | H14: =MAX(0.05,MIN(0.99,Inputs!G4-C14)) -> 0.5 | I14: =Inputs!H4 -> 0.85 | J14: =Inputs!J4 -> 9.3 | K14: =MAX(0.05,MIN(0.99,Inputs!K4-C14)) -> 0.9 | L14: =MAX(0.05,MIN(0.99,Inputs!L4-C14)) -> 0.85 | M14: =D14*E14*J14*((F14+G14)/2)*I14/H14*Parameters!$B$5 -> 3201.525 | N14: =D14*E14*J14*Parameters!$B$4*I14/H14*Parameters!$B$5 -> 1600.7625 | O14: =M14-M14*K14*L14 -> 752.35838 | P14: =O14/N14 -> 0.47 | Q14: =IF(P14<Parameters!$B$6,"Below tolerance",IF(P14<=Parameters!$B$7,"Approximately at tolerance","Above tolerance")) -> Below tolerance
A15: S1 | B15: Central | C15: =0*Parameters!$B$9 -> 0 | D15: =MAX(0.05,MIN(0.99,Inputs!C4+C15)) -> 0.85 | E15: =MAX(0.05,MIN(0.99,Inputs!D4+C15)) -> 0.55 | F15: =MAX(0.05,MIN(0.99,Inputs!E4+C15)) -> 0.55 | G15: =MAX(0.05,MIN(0.99,Inputs!F4+C15)) -> 0.85 | H15: =MAX(0.05,MIN(0.99,Inputs!G4-C15)) -> 0.4 | I15: =Inputs!H4 -> 0.85 | J15: =Inputs!J4 -> 9.3 | K15: =MAX(0.05,MIN(0.99,Inputs!K4-C15)) -> 0.8 | L15: =MAX(0.05,MIN(0.99,Inputs!L4-C15)) -> 0.75 | M15: =D15*E15*J15*((F15+G15)/2)*I15/H15*Parameters!$B$5 -> 6467.2781 | N15: =D15*E15*J15*Parameters!$B$4*I15/H15*Parameters!$B$5 -> 2771.6906 | O15: =M15-M15*K15*L15 -> 2586.9113 | P15: =O15/N15 -> 0.93333333 | Q15: =IF(P15<Parameters!$B$6,"Below tolerance",IF(P15<=Parameters!$B$7,"Approximately at tolerance","Above tolerance")) -> Approximately at tolerance
A16: S1 | B16: Higher | C16: =1*Parameters!$B$9 -> 0.1 | D16: =MAX(0.05,MIN(0.99,Inputs!C4+C16)) -> 0.95 | E16: =MAX(0.05,MIN(0.99,Inputs!D4+C16)) -> 0.65 | F16: =MAX(0.05,MIN(0.99,Inputs!E4+C16)) -> 0.65 | G16: =MAX(0.05,MIN(0.99,Inputs!F4+C16)) -> 0.95 | H16: =MAX(0.05,MIN(0.99,Inputs!G4-C16)) -> 0.3 | I16: =Inputs!H4 -> 0.85 | J16: =Inputs!J4 -> 9.3 | K16: =MAX(0.05,MIN(0.99,Inputs!K4-C16)) -> 0.7 | L16: =MAX(0.05,MIN(0.99,Inputs!L4-C16)) -> 0.65 | M16: =D16*E16*J16*((F16+G16)/2)*I16/H16*Parameters!$B$5 -> 13016.9 | N16: =D16*E16*J16*Parameters!$B$4*I16/H16*Parameters!$B$5 -> 4881.3375 | O16: =M16-M16*K16*L16 -> 7094.2105 | P16: =O16/N16 -> 1.4533333 | Q16: =IF(P16<Parameters!$B$6,"Below tolerance",IF(P16<=Parameters!$B$7,"Approximately at tolerance","Above tolerance")) -> Above tolerance
A17: S8 | B17: Lower | C17: =-1*Parameters!$B$9 -> -0.1 | D17: =MAX(0.05,MIN(0.99,Inputs!C11+C17)) -> 0.7 | E17: =MAX(0.05,MIN(0.99,Inputs!D11+C17)) -> 0.5 | F17: =MAX(0.05,MIN(0.99,Inputs!E11+C17)) -> 0.5 | G17: =MAX(0.05,MIN(0.99,Inputs!F11+C17)) -> 0.8 | H17: =MAX(0.05,MIN(0.99,Inputs!G11-C17)) -> 0.4 | I17: =Inputs!H11 -> 0.85 | J17: =Inputs!J11 -> 9.2 | K17: =MAX(0.05,MIN(0.99,Inputs!K11-C17)) -> 0.8 | L17: =MAX(0.05,MIN(0.99,Inputs!L11-C17)) -> 0.9 | M17: =D17*E17*J17*((F17+G17)/2)*I17/H17*Parameters!$B$5 -> 4447.625 | N17: =D17*E17*J17*Parameters!$B$4*I17/H17*Parameters!$B$5 -> 2052.75 | O17: =M17-M17*K17*L17 -> 1245.335 | P17: =O17/N17 -> 0.60666667 | Q17: =IF(P17<Parameters!$B$6,"Below tolerance",IF(P17<=Parameters!$B$7,"Approximately at tolerance","Above tolerance")) -> Below tolerance
A18: S8 | B18: Central | C18: =0*Parameters!$B$9 -> 0 | D18: =MAX(0.05,MIN(0.99,Inputs!C11+C18)) -> 0.8 | E18: =MAX(0.05,MIN(0.99,Inputs!D11+C18)) -> 0.6 | F18: =MAX(0.05,MIN(0.99,Inputs!E11+C18)) -> 0.6 | G18: =MAX(0.05,MIN(0.99,Inputs!F11+C18)) -> 0.9 | H18: =MAX(0.05,MIN(0.99,Inputs!G11-C18)) -> 0.3 | I18: =Inputs!H11 -> 0.85 | J18: =Inputs!J11 -> 9.2 | K18: =MAX(0.05,MIN(0.99,Inputs!K11-C18)) -> 0.7 | L18: =MAX(0.05,MIN(0.99,Inputs!L11-C18)) -> 0.8 | M18: =D18*E18*J18*((F18+G18)/2)*I18/H18*Parameters!$B$5 -> 9384 | N18: =D18*E18*J18*Parameters!$B$4*I18/H18*Parameters!$B$5 -> 3753.6 | O18: =M18-M18*K18*L18 -> 4128.96 | P18: =O18/N18 -> 1.1 | Q18: =IF(P18<Parameters!$B$6,"Below tolerance",IF(P18<=Parameters!$B$7,"Approximately at tolerance","Above tolerance")) -> Approximately at tolerance
A19: S8 | B19: Higher | C19: =1*Parameters!$B$9 -> 0.1 | D19: =MAX(0.05,MIN(0.99,Inputs!C11+C19)) -> 0.9 | E19: =MAX(0.05,MIN(0.99,Inputs!D11+C19)) -> 0.7 | F19: =MAX(0.05,MIN(0.99,Inputs!E11+C19)) -> 0.7 | G19: =MAX(0.05,MIN(0.99,Inputs!F11+C19)) -> 0.99 | H19: =MAX(0.05,MIN(0.99,Inputs!G11-C19)) -> 0.2 | I19: =Inputs!H11 -> 0.85 | J19: =Inputs!J11 -> 9.2 | K19: =MAX(0.05,MIN(0.99,Inputs!K11-C19)) -> 0.6 | L19: =MAX(0.05,MIN(0.99,Inputs!L11-C19)) -> 0.7 | M19: =D19*E19*J19*((F19+G19)/2)*I19/H19*Parameters!$B$5 -> 20814.885 | N19: =D19*E19*J19*Parameters!$B$4*I19/H19*Parameters!$B$5 -> 7389.9 | O19: =M19-M19*K19*L19 -> 12072.633 | P19: =O19/N19 -> 1.6336667 | Q19: =IF(P19<Parameters!$B$6,"Below tolerance",IF(P19<=Parameters!$B$7,"Approximately at tolerance","Above tolerance")) -> Above tolerance
A21: Appetite sensitivity (central parameters): ratio at alternative appetite values
A22: ID | B22: Appetite 0.20 | C22: Appetite 0.30 | D22: Appetite 0.40
A23: S1 | B23: =Analyse!S5/(Analyse!M5/Analyse!J5*0.2) -> 1.4 | C23: =Analyse!S5/(Analyse!M5/Analyse!J5*0.3) -> 0.93333333 | D23: =Analyse!S5/(Analyse!M5/Analyse!J5*0.4) -> 0.7
A24: S2 | B24: =Analyse!S6/(Analyse!M6/Analyse!J6*0.2) -> 1.8046875 | C24: =Analyse!S6/(Analyse!M6/Analyse!J6*0.3) -> 1.203125 | D24: =Analyse!S6/(Analyse!M6/Analyse!J6*0.4) -> 0.90234375
A25: S3 | B25: =Analyse!S7/(Analyse!M7/Analyse!J7*0.2) -> 1.2 | C25: =Analyse!S7/(Analyse!M7/Analyse!J7*0.3) -> 0.8 | D25: =Analyse!S7/(Analyse!M7/Analyse!J7*0.4) -> 0.6
A26: S4 | B26: =Analyse!S8/(Analyse!M8/Analyse!J8*0.2) -> 1.366875 | C26: =Analyse!S8/(Analyse!M8/Analyse!J8*0.3) -> 0.91125 | D26: =Analyse!S8/(Analyse!M8/Analyse!J8*0.4) -> 0.6834375
A27: S5 | B27: =Analyse!S9/(Analyse!M9/Analyse!J9*0.2) -> 1.83 | C27: =Analyse!S9/(Analyse!M9/Analyse!J9*0.3) -> 1.22 | D27: =Analyse!S9/(Analyse!M9/Analyse!J9*0.4) -> 0.915
A28: S6 | B28: =Analyse!S10/(Analyse!M10/Analyse!J10*0.2) -> 1.51875 | C28: =Analyse!S10/(Analyse!M10/Analyse!J10*0.3) -> 1.0125 | D28: =Analyse!S10/(Analyse!M10/Analyse!J10*0.4) -> 0.759375
A29: S7 | B29: =Analyse!S11/(Analyse!M11/Analyse!J11*0.2) -> 2.175 | C29: =Analyse!S11/(Analyse!M11/Analyse!J11*0.3) -> 1.45 | D29: =Analyse!S11/(Analyse!M11/Analyse!J11*0.4) -> 1.0875
A30: S8 | B30: =Analyse!S12/(Analyse!M12/Analyse!J12*0.2) -> 1.65 | C30: =Analyse!S12/(Analyse!M12/Analyse!J12*0.3) -> 1.1 | D30: =Analyse!S12/(Analyse!M12/Analyse!J12*0.4) -> 0.825
A31: S9 | B31: =Analyse!S13/(Analyse!M13/Analyse!J13*0.2) -> 2.30625 | C31: =Analyse!S13/(Analyse!M13/Analyse!J13*0.3) -> 1.5375 | D31: =Analyse!S13/(Analyse!M13/Analyse!J13*0.4) -> 1.153125
A32: S10 | B32: =Analyse!S14/(Analyse!M14/Analyse!J14*0.2) -> 1.78125 | C32: =Analyse!S14/(Analyse!M14/Analyse!J14*0.3) -> 1.1875 | D32: =Analyse!S14/(Analyse!M14/Analyse!J14*0.4) -> 0.890625

Sheet Case_View
A1: Case-native escalation view (Business case s.8) - secondary cross-check
A2: Normalized residual = T x E x I x (1 - C), with T = Pb(A), E = Pb(psi,A), I = (de+dm)/2, C (control maturity) proxied by theta. Post-treatment = current x (1 - P x Q). Analyst mapping - validate.
A4: ID | B4: T | C4: E | D4: I | E4: C (theta) | F4: Current residual | G4: Level | H4: Post-treatment residual | I4: Level | J4: Acceptance authority (post)
A5: S1 | B5: =Inputs!C4 -> 0.85 | C5: =Inputs!D4 -> 0.55 | D5: =(Inputs!E4+Inputs!F4)/2 -> 0.7 | E5: =Inputs!G4 -> 0.4 | F5: =B5*C5*D5*(1-E5) -> 0.19635 | G5: =IF(F5<=0.07,"Low",IF(F5<=0.15,"Moderate",IF(F5<=0.25,"High","Critical"))) -> High | H5: =F5*(1-Inputs!K4*Inputs!L4) -> 0.07854 | I5: =IF(H5<=0.07,"Low",IF(H5<=0.15,"Moderate",IF(H5<=0.25,"High","Critical"))) -> Moderate | J5: =IF(H5>Parameters!$B$11,"Board / ownership group",IF(H5>Parameters!$B$10,"Executive leadership","CIO / Cybersecurity lead")) -> CIO / Cybersecurity lead
A6: S2 | B6: =Inputs!C5 -> 0.75 | C6: =Inputs!D5 -> 0.5 | D6: =(Inputs!E5+Inputs!F5)/2 -> 0.825 | E6: =Inputs!G5 -> 0.35 | F6: =B6*C6*D6*(1-E6) -> 0.20109375 | G6: =IF(F6<=0.07,"Low",IF(F6<=0.15,"Moderate",IF(F6<=0.25,"High","Critical"))) -> High | H6: =F6*(1-Inputs!K5*Inputs!L5) -> 0.087978516 | I6: =IF(H6<=0.07,"Low",IF(H6<=0.15,"Moderate",IF(H6<=0.25,"High","Critical"))) -> Moderate | J6: =IF(H6>Parameters!$B$11,"Board / ownership group",IF(H6>Parameters!$B$10,"Executive leadership","CIO / Cybersecurity lead")) -> CIO / Cybersecurity lead
A7: S3 | B7: =Inputs!C6 -> 0.55 | C7: =Inputs!D6 -> 0.5 | D7: =(Inputs!E6+Inputs!F6)/2 -> 0.75 | E7: =Inputs!G6 -> 0.35 | F7: =B7*C7*D7*(1-E7) -> 0.1340625 | G7: =IF(F7<=0.07,"Low",IF(F7<=0.15,"Moderate",IF(F7<=0.25,"High","Critical"))) -> Moderate | H7: =F7*(1-Inputs!K6*Inputs!L6) -> 0.0429 | I7: =IF(H7<=0.07,"Low",IF(H7<=0.15,"Moderate",IF(H7<=0.25,"High","Critical"))) -> Low | J7: =IF(H7>Parameters!$B$11,"Board / ownership group",IF(H7>Parameters!$B$10,"Executive leadership","CIO / Cybersecurity lead")) -> CIO / Cybersecurity lead
A8: S4 | B8: =Inputs!C7 -> 0.6 | C8: =Inputs!D7 -> 0.45 | D8: =(Inputs!E7+Inputs!F7)/2 -> 0.675 | E8: =Inputs!G7 -> 0.4 | F8: =B8*C8*D8*(1-E8) -> 0.10935 | G8: =IF(F8<=0.07,"Low",IF(F8<=0.15,"Moderate",IF(F8<=0.25,"High","Critical"))) -> Moderate | H8: =F8*(1-Inputs!K7*Inputs!L7) -> 0.04428675 | I8: =IF(H8<=0.07,"Low",IF(H8<=0.15,"Moderate",IF(H8<=0.25,"High","Critical"))) -> Low | J8: =IF(H8>Parameters!$B$11,"Board / ownership group",IF(H8>Parameters!$B$10,"Executive leadership","CIO / Cybersecurity lead")) -> CIO / Cybersecurity lead
A9: S5 | B9: =Inputs!C8 -> 0.6 | C9: =Inputs!D8 -> 0.55 | D9: =(Inputs!E8+Inputs!F8)/2 -> 0.6 | E9: =Inputs!G8 -> 0.4 | F9: =B9*C9*D9*(1-E9) -> 0.1188 | G9: =IF(F9<=0.07,"Low",IF(F9<=0.15,"Moderate",IF(F9<=0.25,"High","Critical"))) -> Moderate | H9: =F9*(1-Inputs!K8*Inputs!L8) -> 0.072468 | I9: =IF(H9<=0.07,"Low",IF(H9<=0.15,"Moderate",IF(H9<=0.25,"High","Critical"))) -> Moderate | J9: =IF(H9>Parameters!$B$11,"Board / ownership group",IF(H9>Parameters!$B$10,"Executive leadership","CIO / Cybersecurity lead")) -> CIO / Cybersecurity lead
A10: S6 | B10: =Inputs!C9 -> 0.8 | C10: =Inputs!D9 -> 0.5 | D10: =(Inputs!E9+Inputs!F9)/2 -> 0.75 | E10: =Inputs!G9 -> 0.4 | F10: =B10*C10*D10*(1-E10) -> 0.18 | G10: =IF(F10<=0.07,"Low",IF(F10<=0.15,"Moderate",IF(F10<=0.25,"High","Critical"))) -> High | H10: =F10*(1-Inputs!K9*Inputs!L9) -> 0.0729 | I10: =IF(H10<=0.07,"Low",IF(H10<=0.15,"Moderate",IF(H10<=0.25,"High","Critical"))) -> Moderate | J10: =IF(H10>Parameters!$B$11,"Board / ownership group",IF(H10>Parameters!$B$10,"Executive leadership","CIO / Cybersecurity lead")) -> CIO / Cybersecurity lead
A11: S7 | B11: =Inputs!C10 -> 0.45 | C11: =Inputs!D10 -> 0.5 | D11: =(Inputs!E10+Inputs!F10)/2 -> 0.75 | E11: =Inputs!G10 -> 0.35 | F11: =B11*C11*D11*(1-E11) -> 0.1096875 | G11: =IF(F11<=0.07,"Low",IF(F11<=0.15,"Moderate",IF(F11<=0.25,"High","Critical"))) -> Moderate | H11: =F11*(1-Inputs!K10*Inputs!L10) -> 0.06361875 | I11: =IF(H11<=0.07,"Low",IF(H11<=0.15,"Moderate",IF(H11<=0.25,"High","Critical"))) -> Low | J11: =IF(H11>Parameters!$B$11,"Board / ownership group",IF(H11>Parameters!$B$10,"Executive leadership","CIO / Cybersecurity lead")) -> CIO / Cybersecurity lead
A12: S8 | B12: =Inputs!C11 -> 0.8 | C12: =Inputs!D11 -> 0.6 | D12: =(Inputs!E11+Inputs!F11)/2 -> 0.75 | E12: =Inputs!G11 -> 0.3 | F12: =B12*C12*D12*(1-E12) -> 0.252 | G12: =IF(F12<=0.07,"Low",IF(F12<=0.15,"Moderate",IF(F12<=0.25,"High","Critical"))) -> Critical | H12: =F12*(1-Inputs!K11*Inputs!L11) -> 0.11088 | I12: =IF(H12<=0.07,"Low",IF(H12<=0.15,"Moderate",IF(H12<=0.25,"High","Critical"))) -> Moderate | J12: =IF(H12>Parameters!$B$11,"Board / ownership group",IF(H12>Parameters!$B$10,"Executive leadership","CIO / Cybersecurity lead")) -> CIO / Cybersecurity lead
A13: S9 | B13: =Inputs!C12 -> 0.55 | C13: =Inputs!D12 -> 0.45 | D13: =(Inputs!E12+Inputs!F12)/2 -> 0.75 | E13: =Inputs!G12 -> 0.35 | F13: =B13*C13*D13*(1-E13) -> 0.12065625 | G13: =IF(F13<=0.07,"Low",IF(F13<=0.15,"Moderate",IF(F13<=0.25,"High","Critical"))) -> Moderate | H13: =F13*(1-Inputs!K12*Inputs!L12) -> 0.074203594 | I13: =IF(H13<=0.07,"Low",IF(H13<=0.15,"Moderate",IF(H13<=0.25,"High","Critical"))) -> Moderate | J13: =IF(H13>Parameters!$B$11,"Board / ownership group",IF(H13>Parameters!$B$10,"Executive leadership","CIO / Cybersecurity lead")) -> CIO / Cybersecurity lead
A14: S10 | B14: =Inputs!C13 -> 0.3 | C14: =Inputs!D13 -> 0.4 | D14: =(Inputs!E13+Inputs!F13)/2 -> 0.75 | E14: =Inputs!G13 -> 0.4 | F14: =B14*C14*D14*(1-E14) -> 0.054 | G14: =IF(F14<=0.07,"Low",IF(F14<=0.15,"Moderate",IF(F14<=0.25,"High","Critical"))) -> Low | H14: =F14*(1-Inputs!K13*Inputs!L13) -> 0.02565 | I14: =IF(H14<=0.07,"Low",IF(H14<=0.15,"Moderate",IF(H14<=0.25,"High","Critical"))) -> Low | J14: =IF(H14>Parameters!$B$11,"Board / ownership group",IF(H14>Parameters!$B$10,"Executive leadership","CIO / Cybersecurity lead")) -> CIO / Cybersecurity lead

Sheet Scenarios
A1: ID | B1: Library ref | C1: Scenario | D1: Statement | E1: Threat source | F1: Vulnerabilities / conditions | G1: Existing controls (evidence) | H1: Treatment package | I1: Initiatives | J1: Risk owner | K1: Horizon | L1: CVSS rationale
A2: S1 | B2: MED-CYR-01 / 12 | C2: Credential compromise of clinical administrator accounts through phishing and MFA fatigue | D2: A financially motivated external actor phishes clinic administrators and billing staff with an EHR-themed lure, captures credentials and obtains approval of an MFA push prompt, gaining remote access to the EHR, billing and administrative systems, enabling unauthorized access to patient records and follow-on intrusion. | E2: Cybercriminal (initial-access broker or ransomware affiliate). | F2: Push-based MFA without number matching or phishing resistance (E6 - validate); No evidence of conditional access (geo/device) policies; Internet-sourced macro documents reach users (E6); Awareness programme maturity unknown (Information gap) | G2: Email filtering / antimalware (E2 - effectiveness unknown); MFA push on remote access (E6); EDR alerting (E6 - triage weak) | H2: Phishing-resistant MFA and conditional access (I01) is the primary lever; PAM (I02) limits blast radius; MDR (I03) shortens dwell time; awareness and reporting (I12). | I2: I01, I02, I03, I12 | J2: CIO | K2: 0-6 months | L2: Representative weakness: remote-access authentication accepting MFA push approval (CWE-308-type single-channel weakness). AV:N internet-reachable gateway; AC:L no special conditions; AT:N; PR:N attacker starts unauthenticated; UI:A user must actively approve; VC/VI:H full session on gateway; VA:N; SC:H EHR data behind the gateway; SI:L/SA:L limited downstream change/disruption. Applicability: moderate - human factor dominates.
A3: S2 | B3: MED-CYR-02 | C3: Ransomware disrupting EHR access and clinic operations across the network | D3: A ransomware group gains a foothold through a macro-enabled phishing attachment or exposed service, moves laterally across an insufficiently segmented network, exfiltrates health data and encrypts EHR support servers, shared folders and scheduling systems, halting clinical and administrative operations at multiple clinics. | E3: Ransomware-as-a-service affiliate (double extortion). | F3: Macro execution and weak alert triage (E6); Segmentation between clinics, servers and backups not evidenced (E2, E7); Privileged credential hygiene unknown (Information gap); Clinic downtime procedures untested (E7) | G3: Firewalls, IDS/IPS, antimalware (E2); EDR (E6); On-site and off-site backups (E2 - isolation and testing unknown); Incident command structure defined (E6 - untested) | H3: Layered: MDR/EDR (I03), PAM (I02), segmentation (I06), immutable backup (I04), patching (I05), IR and downtime procedures (I11), awareness (I12). Residual remains material - consider cyber-insurance transfer. | I3: I02, I03, I04, I05, I06, I11, I12 | J3: Executive leadership (COO) with CIO | K3: 0-24 months | L3: Representative weakness: malicious macro document leading to code execution (initial vector in E6). AV:L - the document is delivered by e-mail but opened locally on the workstation (FIRST CVSS v4.0 user guide: document-based weaknesses are Local whatever the delivery channel); AC:L; AT:N; PR:N; UI:P user opens the document; VC/VI/VA:H on the workstation; SC/SI/SA:H because EHR and clinic systems are subsequently affected. CVSS describes the entry weakness only, not the enterprise impact.
A4: S3 | B4: MED-CYR-07 | C4: Backup environment compromised, preventing recovery after a destructive attack | D4: An attacker holding administrative credentials reaches backup servers that share the production identity domain and network, deletes or encrypts backup sets and clinic storage copies, so that MediBec cannot restore EHR and clinic systems within clinically acceptable time after a destructive event. | E4: Ransomware operator or other attacker with administrative access. | F4: Backup consoles authenticated through production directory (Analyst assumption - validate); No immutable or offline copy evidenced; Restore testing and RTO/RPO not evidenced (E7); Backup failure alerts not escalated (E6) | G4: On-site and off-site backups (E2); Encrypted storage (E2) | H4: Immutable/offline copies with separate backup identity (I04), segmentation (I06), PAM (I02), backup-alert monitoring (I03), quarterly restore tests and IR integration (I11). | I4: I02, I03, I04, I06, I11 | J4: CIO | K4: 0-9 months | L4: Representative weakness: backup management console reachable from production network and trusting production administrator accounts. PR:H attacker already holds admin credentials; VC/VI/VA:H on the backup system; SA:H because recovery of all subsequent systems is lost.
A5: S4 | B5: MED-CYR-03 | C5: Cloud medical-image transfer storage exposed, enabling bulk health-data exfiltration | D5: An opportunistic or targeted actor discovers a cloud storage location used for medical-image transfer and exports that is shared through long-lived public or weakly authenticated links, downloads large volumes of images and associated patient identifiers, and causes a large-scale health-data breach. | E5: Opportunistic scanner or cybercriminal data broker. | F5: Permissive or long-lived sharing links (Analyst assumption); No cloud posture management evidenced; Object-level access logging unknown (E4); Exports contain identifiers alongside images | G5: Encrypted storage (E2 - at-rest only, not access control); Cloud access via identity (E2) | H5: Block public access and enforce expiring authenticated links (I08); DLP and data minimization in exports (I09); object-access logging to MDR (I03). | I5: I03, I08, I09 | J5: CIO with Privacy officer | K5: 0-6 months | L5: Representative weakness: storage object accessible without authentication (CWE-284 misconfiguration). AV:N, AC:L, AT:N, PR:N, UI:N; confidentiality only (VC:H).
A6: S5 | B6: MED-CYR-11 (+ service-account evidence) | C6: Misuse of legitimate clinical, privileged or service-account access to extract patient records | D6: A malicious or curious insider, or an attacker who has taken over the over-privileged ehr-sync-svc service account, uses legitimate but excessive EHR access to query and export large volumes of patient or billing records without triggering review, resulting in a privacy breach and loss of trust. | E6: Malicious or negligent insider; external actor using a service account. | F6: Broad role-based access in EHR (Analyst assumption); Over-privileged service account without vaulting (E6); No EHR access analytics or periodic recertification evidenced (E7); No DLP evidenced | G6: EHR audit log exists (E6); Encrypted storage (E2) | H6: Least-privilege redesign and access recertification plus EHR access analytics and DLP (I09); vault and restrict service accounts (I02); MDR use-cases (I03); HR/awareness (I12). | I6: I02, I03, I09, I12 | J6: Privacy officer | K6: 3-12 months | L6: Limited applicability: insider misuse is not a software vulnerability. Representative weakness used for the workbook: excessive privileges on an authenticated account (CWE-269). PR:L legitimate low-privilege access; VC:H bulk read; VI:L. Interpret with caution.
A7: S6 | B7: MED-CYR-06 | C7: Exploitation of unpatched internet-facing or end-of-life systems | D7: A cybercriminal or state-linked actor mass-exploits a known vulnerability in an internet-facing remote access gateway, firewall or web application that MediBec has not patched because of uptime concerns, vendor constraints or limited staff, obtaining remote code execution and a foothold for data theft or ransomware. | E7: Cybercriminal / state-linked actor using public exploits. | F7: Patch SLAs and exception governance not evidenced (E7); Incomplete asset inventory (E4); Possible end-of-life systems (Information gap) | G7: Firewalls, IDS/IPS (E2); Antimalware (E2) | H7: Risk-based vulnerability and patch management with KEV SLAs and EOL retirement (I05); segmentation behind the edge (I06); MDR threat hunting (I03). | I7: I03, I05, I06 | J7: CIO | K7: 1-9 months | L7: Representative weakness: unauthenticated remote code execution in an internet-facing gateway (typical of known-exploited edge vulnerabilities). All impacts High because the gateway fronts the internal network. Replace with the actual CVE vector once scan data is available.
A8: S7 | B8: MED-CYR-09 (+ Wi-Fi path MED-CYR-05) | C8: Connected medical device used as a foothold to disrupt clinical equipment and reach the EHR network | D8: An attacker reaching a clinic network (through malware, a compromised clinic Wi-Fi or vendor access) exploits an unpatched or default-credential medical device on a network shared with EHR workstations, disrupting device operation and using it as a persistent foothold, with potential consequences for patient care. | E8: Cybercriminal (opportunistic or during ransomware operation). | F8: Incomplete device inventory (E4); Embedded OS patching restricted by certification (E3); Devices and guest/clinical Wi-Fi not segmented (E4, E7 - validate); Default credentials (Analyst assumption) | G8: Firewalls and IDS/IPS at hub (E2 - east-west coverage unknown) | H8: Medical device security programme (I07), segmentation and NAC including guest Wi-Fi isolation (I06), patch/compensating controls (I05). Residual depends on manufacturers. | I8: I05, I06, I07 | J8: Clinical Ops with Biomedical engineering | K8: 3-24 months | L8: Representative weakness: unpatched embedded service or default credential on a networked device. AV:A reachable from the clinic LAN/Wi-Fi only; PR:N; full device impact; SC/SI/SA:L onward effects. CVSS supplemental metric Safety (S:P) would apply but is not part of the base score.
A9: S8 | B9: MED-CYR-08 / 15 | C9: Detection and response gaps allow an intrusion to persist and escalate | D9: An intrusion by any external actor goes unnoticed or is misclassified because alert triage, log coverage and after-hours monitoring are insufficient for a two-person cybersecurity team, and the untested incident response plan leads to slow, uncoordinated containment, turning a contained event into a major privacy and operational incident. | E9: Any external actor (amplifier scenario). | F9: No 24/7 monitoring (E3 - inferred); Alert triage criteria weak (E6); Log coverage and retention unknown (E4); IR plan untested; decision rights unclear (E8) | G9: IDS/IPS (E2); EDR (E6); Incident command roles defined (E6) | H9: 24/7 MDR with centralized logging and escalation criteria (I03); IR plan, playbooks, retainer and tabletop exercises across clinics (I11); governance reporting (I12). | I9: I01, I03, I11, I12 | J9: Cybersecurity lead | K9: 0-6 months | L9: Limited applicability: a detection gap is a control weakness, not a vulnerability. Representative weakness for the workbook: the undetected initial code-execution vector (macro/PowerShell, E6); AV:L because the malicious document is opened locally. Do not interpret the score as the severity of the detection gap.
A10: S9 | B10: MED-CYR-14 | C10: Compromise of a critical vendor with remote access to MediBec systems | D10: A threat actor compromises an EHR, diagnostic, device or IT support vendor and uses the vendor's standing remote access or software update channel to enter MediBec's environment, bypassing perimeter controls to access health data or deploy malware. | E10: Supply-chain attacker (cybercriminal or state-linked). | F10: Standing vendor remote access (Analyst assumption); No vendor tiering or assessments evidenced (E7); Incident-notification clauses unknown (E5); Vendor sessions not brokered or recorded | G10: Firewalls (E2); Vendor coordination role defined for incidents (E6) | H10: Third-party risk programme and contract clauses (I10); vendor access only through PAM with MFA and recording (I01/I02); MDR monitoring of vendor sessions (I03); joint IR (I11). Residual largely outside MediBec's control - consider contractual and insurance transfer. | I10: I01, I02, I03, I10, I11 | J10: Procurement with CIO | K10: 2-12 months | L10: Limited applicability: supplier concentration is not a single vulnerability. Representative weakness: standing authenticated remote-access channel. AT:P the vendor must first be compromised; PR:L vendor account; full impacts. Validate against actual vendor access design.
A11: S10 | B11: MED-CYR-13 | C11: Manipulation of patient, medication or billing records undermining clinical decisions | D11: An attacker with compromised clinical credentials, or a malicious insider, alters medication, allergy, laboratory or billing records in the EHR or pharmacy system without detection, leading to incorrect clinical decisions, patient harm and loss of confidence in the record. | E11: External attacker (extortion or sabotage) or malicious insider. | F11: No integrity monitoring or reconciliation evidenced (E8); Broad write privileges (Analyst assumption); Audit trail review not evidenced; Post-restore integrity verification absent | G11: EHR audit logging (E6); Encrypted storage (E2 - no integrity protection) | H11: Integrity monitoring and reconciliation (I13), least-privilege write access (I09/I02), strong authentication (I01), backup-based verification (I04), MDR (I03), clinical playbook (I11). | I11: I01, I02, I03, I04, I09, I11, I13 | J11: Clinical Ops (CMO) | K11: 3-15 months | L11: Representative weakness: authenticated user able to modify records beyond need (improper authorization, CWE-285). PR:L; VI:H; SI:H because pharmacy/lab downstream systems consume the altered data.

Sheet Candidates
A1: ID | B1: Candidate scenario | C1: Threat source | D1: Vulnerability / condition | E1: Primary asset | F1: Undesired outcome | G1: Library ref | H1: Decision | I1: Screening rationale
A2: C01 | B2: Phishing-led compromise of clinic administrator credentials | C2: Cybercriminal | D2: Push-based MFA susceptible to fatigue; macro attachments delivered | E2: CJ5 / CJ1 | F2: Unauthorized EHR and remote access | G2: MED-CYR-01, 12 | H2: Selected (S1) | I2: Most frequent initial-access path; directly evidenced by injects E6.
A3: C02 | B3: Ransomware encrypting EHR support systems, shared folders and scheduling | C3: Ransomware group | D3: Flat internal network; weak alert triage; backups reachable | E3: CJ1 / CJ3 / CJ6 | F3: Multi-clinic disruption and data theft | G3: MED-CYR-02 | H3: Selected (S2) | I3: Highest combined clinical, privacy and operational consequence.
A4: C03 | B4: Backup environment compromised before encryption, recovery fails | C4: Ransomware group / privileged attacker | D4: Backups in same admin domain; restore testing not evidenced | E4: CJ6 | F4: Prolonged outage, loss of recoverability | G4: MED-CYR-07 | H4: Selected (S3) | I4: Determines whether S2 is survivable; backup failures in E6.
A5: C04 | B5: Cloud medical-image transfer storage exposed or accessed externally | C5: Opportunistic actor / cybercriminal | D5: Permissive sharing, weak cloud logging and posture management | E5: CJ7 | F5: Bulk health-data exposure | G5: MED-CYR-03 | H5: Selected (S4) | I5: Large-volume PHI exposure; evidenced by unusual downloads (E6).
A6: C05 | B6: API key committed to a code repository enables data access | C6: Opportunistic actor | D6: No secret scanning or vault evidenced | E6: CJ1 / CJ7 | F6: Direct API data extraction | G6: MED-CYR-04 | H6: Not selected | I6: Plausible but thin evidence on MediBec's development footprint; controls partly shared with S4/S5. Keep on watch list.
A7: C06 | B7: Clinic Wi-Fi compromise or rogue access point | C7: Local attacker | D7: Guest/clinical Wi-Fi segmentation not evidenced | E7: Clinic LAN | F7: Internal network foothold | G7: MED-CYR-05 | H7: Merged into S7 | I7: Treated as an access path; the consequence driver is the flat network addressed in S7/S2.
A8: C07 | B8: Exploitation of unpatched internet-facing or end-of-life systems | C8: Cybercriminal / state-linked actor | D8: Patch delays from uptime and vendor constraints | E8: CJ5 / CJ6 | F8: Remote code execution and intrusion | G8: MED-CYR-06 | H8: Selected (S6) | I8: Mass exploitation of edge devices is a leading entry vector; patching constraints documented (E3).
